<?xml version="1.0"?>
<robot name="slambot">

  <link name="base_link"/>
  <link name="right_wheel"/>
  <link name="left_wheel"/>
  <link name="laser"/>

  <joint name="left_wheel_joint" type="continuous">
    <parent link="base_link"/>
    <child link="left_wheel"/>
    <origin xyz="-0.075 0.025 0.0" rpy="0 0 0"/>
    <axis xyz="0 1 0"/>
  </joint>

  <joint name="right_wheel_joint" type="continuous">
    <parent link="base_link"/>
    <child link="right_wheel"/>
    <origin xyz="-0.075 -0.025 0.0" rpy="0 0 3.14"/>
    <axis xyz="0 1 0"/>
  </joint>

  <joint name="laser_joint" type="fixed">
    <parent link="base_link"/>
    <child link="laser"/>
    <origin xyz="0.0 0.0 0.1" rpy="1.57 0 0"/>
  </joint>


  <ros2_control name="Slambot" type="system">
    <hardware>
      <plugin>mock_components/GenericSystem</plugin>
      <param name="calculate_dynamics">true</param>
    </hardware>
    <joint name="left_wheel_joint">
      <command_interface name="velocity"/>
      <state_interface name="velocity"/>
      <state_interface name="position">
        <param name="initial_value">0.0</param>
      </state_interface>
    </joint>
    <joint name="right_wheel_joint">
      <command_interface name="velocity"/>
      <state_interface name="velocity"/>
      <state_interface name="position">
        <param name="initial_value">0.0</param>
      </state_interface>
    </joint>
  </ros2_control>



</robot>